Workbook
Name Slicer_State_Abbr: #N/A

Sheet CurrentYearData
A1: Category | B1: Rev | C1: State | D1: 44562 | E1: 44593 | F1: 44621 | G1: 44652 | H1: 44682 | I1: 44713 | J1: 44743 | K1: 44774 | L1: 44805 | M1: 44835 | N1: 44866 | O1: 44896 | Q1: State Name | R1: State Abbr | S1: Row Labels
A2: Revenue | B2: Actual | C2: MI | D2: 753066 | E2: 852656 | F2: 618949 | G2: 721280 | H2: 515660 | I2: 429226 | J2: 703800 | K2: 761300 | L2: 752100 | M2: 736000 | N2: 678500 | O2: 692300 | Q2: New York | R2: NY | S2: WA
A3: Revenue | B3: Actual | C3: TX | D3: 359053 | E3: 626773 | F3: 394933 | G3: 442792 | H3: 424350 | I3: 516810 | J3: 535900 | K3: 526700 | L3: 512900 | M3: 496800 | N3: 517500 | O3: 492200 | Q3: Virginia | R3: VA
A4: Revenue | B4: Actual | C4: CO | D4: 357420 | E4: 295573 | F4: 368368 | G4: 331890 | H4: 306544 | I4: 327060 | J4: 425500 | K4: 416300 | L4: 404800 | M4: 425500 | N4: 450800 | O4: 414000 | Q4: Florida | R4: FL
A5: Revenue | B5: Actual | C5: VA | D5: 832048 | E5: 873264 | F5: 489762 | G5: 621690 | H5: 902520 | I5: 901968 | J5: 742900 | K5: 772800 | L5: 777400 | M5: 731400 | N5: 752100 | O5: 791200 | Q5: Michigan | R5: MI
A6: Revenue | B6: Actual | C6: KS | D6: 718865 | E6: 904590 | F6: 537740 | G6: 801136 | H6: 885776 | I6: 469062 | J6: 756700 | K6: 786600 | L6: 768200 | M6: 715300 | N6: 763600 | O6: 710700 | Q6: Texas | R6: TX
A7: Revenue | B7: Actual | C7: FL | D7: 816546 | E7: 679558 | F7: 966276 | G7: 610650 | H7: 684614 | I7: 643057 | J7: 841800 | K7: 860200 | L7: 894700 | M7: 814200 | N7: 823400 | O7: 880900 | Q7: Kansas | R7: KS
A8: Revenue | B8: Actual | C8: WA | D8: 233404 | E8: 142968 | F8: 190026 | G8: 169802 | H8: 188350 | I8: 178272 | J8: 197800 | K8: 193200 | L8: 186300 | M8: 177100 | N8: 172500 | O8: 156400 | Q8: Colorado | R8: CO
A9: Revenue | B9: Actual | C9: NY | D9: 920920 | E9: 1311161 | F9: 1025133 | G9: 1354286 | H9: 892584 | I9: 998020 | J9: 1196000 | K9: 1202900 | L9: 1235100 | M9: 1147700 | N9: 1159200 | O9: 1276500 | Q9: Washington | R9: WA
A11: Revenue | B11: Plan | C11: MI | D11: 744029.21 | E11: 874825.06 | F11: 453561.43 | G11: 678363.84 | H11: 514370.85 | I11: 498152.93 | J11: 695354.4 | K11: 781093.8 | L11: 657335.4 | M11: 692208 | N11: 676803.75 | O11: 690569.25
A12: Revenue | B12: Plan | C12: TX | D12: 344511.35 | E12: 607343.04 | F12: 551449.39 | G12: 512626.3 | H12: 462819.25 | I12: 630247.06 | J12: 514196.05 | K12: 510372.3 | L12: 521362.85 | M12: 453081.6 | N12: 442462.5 | O12: 504997.2 | Q12: Option Button | R12: 1
A13: Revenue | B13: Plan | C13: CO | D13: 308989.59 | E13: 269562.58 | F13: 335951.62 | G13: 308989.59 | H13: 297041.14 | I13: 313814.07 | J13: 367844.75 | K13: 379665.6 | L13: 369177.6 | M13: 396140.5 | N13: 436825.2 | O13: 397233 | Q13: Revenue | R13: {=INDEX(Q13:Q15, R12)} -> Revenue
A14: Revenue | B14: Plan | C14: VA | D14: 778601.04 | E14: 796416.77 | F14: 697843.07 | G14: 631947.89 | H14: 771654.6 | I14: 771182.64 | J14: 695179.5 | K14: 704793.6 | L14: 790227.1 | M14: 743468.1 | N14: 643045.5 | O14: 676476 | Q14: Expense
A15: Revenue | B15: Plan | C15: KS | D15: 838306.41 | E15: 1014950 | F15: 827004.84 | G15: 845999.62 | H15: 896405.31 | I15: 790169.79 | J15: 882427.8 | K15: 882565.2 | L15: 895721.2 | M15: 755356.8 | N15: 772763.2 | O15: 742681.5 | Q15: EBIT
A16: Revenue | B16: Plan | C16: FL | D16: 752447.14 | E16: 632668.5 | F16: 963860.31 | G16: 580117.5 | H16: 666490.97 | I16: 710904.15 | J16: 775718.7 | K16: 800846.2 | L16: 892463.25 | M16: 773490 | N16: 797874.6 | O16: 836855
A17: Revenue | B17: Plan | C17: WA | D17: 227514.62 | E17: 130203 | F17: 159528 | G17: 188725.72 | H17: 113141.6 | I17: 117072.76 | J17: 192809 | K17: 175950 | L17: 156400 | M17: 143106 | N17: 131560 | O17: 119462
A18: Revenue | B18: Plan | C18: NY | D18: 962361.4 | E18: 1312472.2 | F18: 1071264 | G18: 1415228.9 | H18: 913113.43 | I18: 976149.25 | J18: 1249820 | K18: 1204102.9 | L18: 1290679.5 | M18: 1199346.5 | N18: 1185861.6 | O18: 1435513.6
A20: Expense | B20: Actual | C20: MI | D20: 460472.49 | E20: 366176.39 | F20: 576698.33 | G20: 477601.31 | H20: 291949.25 | I20: 324453.81 | J20: 613277.24 | K20: 648444.89 | L20: 609201 | M20: 672468.48 | N20: 585491.22 | O20: 601885.62
A21: Expense | B21: Actual | C21: TX | D21: 339602.98 | E21: 236237.03 | F21: 343229.3 | G21: 363797.87 | H21: 367587.43 | I21: 441283.39 | J21: 443725.2 | K21: 435680.97 | L21: 446469.19 | M21: 453916.22 | N21: 398216.25 | O21: 387253.12
A22: Expense | B22: Actual | C22: CO | D22: 192524.28 | E22: 229771.25 | F22: 179766.42 | G22: 203729.4 | H22: 264191.88 | I22: 164376.59 | J22: 331213.46 | K22: 338102.21 | L22: 325337.76 | M22: 320605.74 | N22: 343360.84 | O22: 363359.52
A23: Expense | B23: Actual | C23: VA | D23: 318841.05 | E23: 471077.43 | F23: 431528.9 | G23: 266891.85 | H23: 401697.66 | I23: 532819.56 | J23: 565644.06 | K23: 706091.9 | L23: 610803.18 | M23: 533190.6 | N23: 572648.94 | O23: 589673.45
A24: Expense | B24: Actual | C24: KS | D24: 628118.06 | E24: 461166.27 | F24: 508439.95 | G24: 458823.99 | H24: 560078.61 | I24: 422177.7 | J24: 582553.06 | K24: 632190.42 | L24: 578685.06 | M24: 527247.63 | N24: 678305.88 | O24: 541318.87
A25: Expense | B25: Actual | C25: FL | D25: 535053.97 | E25: 581036.8 | F25: 567606.63 | G25: 437984.07 | H25: 643317.4 | I25: 527165.93 | J25: 703222.88 | K25: 662388.41 | L25: 741375.26 | M25: 701929.96 | N25: 737428.81 | O25: 663581.97
A26: Expense | B26: Actual | C26: WA | D26: 100687.53 | E26: 95851.35 | F26: 100354.84 | G26: 120197.77 | H26: 182715.44 | I26: 158149.82 | J26: 153969.5 | K26: 160178.26 | L26: 162338.09 | M26: 143785.72 | N26: 150313.05 | O26: 120349.8
A27: Expense | B27: Actual | C27: NY | D27: 535349.69 | E27: 629031.92 | F27: 549722.16 | G27: 526267.51 | H27: 719016.58 | I27: 990627.39 | J27: 1049705.3 | K27: 1027829.9 | L27: 951076.4 | M27: 836673.3 | N27: 939890.95 | O27: 1153904.9
A29: Expense | B29: Plan | C29: MI | D29: 657817.85 | E29: 523109.12 | F29: 423854.76 | G29: 482287.59 | H29: 417070.36 | I29: 463505.44 | J29: 607766.49 | K29: 676947.96 | L29: 636615.05 | M29: 604108.8 | N29: 562713.97 | O29: 615593.16
... A36: Expense | B36: Plan | C36: NY | D36: 682007.04 | E36: 854021.29 | F36: 765757.48 | G36: 781948.67 | H36: 870876.37 | I36: 800564.19 | J36: 1136678.4 | K36: 1186140.7 | L36: 1126113.9 | M36: 1056687.4 | N36: 1078751.5 | O36: 1086697.2
A38: EBIT | B38: Actual | C38: MI | D38: =D2-D20 -> 292593.51 | E38: =E2-E20 -> 486479.61 | F38: =F2-F20 -> 42250.665 | G38: =G2-G20 -> 243678.69 | H38: =H2-H20 -> 223710.75 | I38: =I2-I20 -> 104772.19 | J38: =J2-J20 -> 90522.756 | K38: =K2-K20 -> 112855.11 | ... O38: =O2-O20 -> 90414.38
A39: EBIT | B39: Actual | C39: TX | D39: =D3-D21 -> 19450.018 | E39: =E3-E21 -> 390535.97 | F39: =F3-F21 -> 51703.699 | G39: =G3-G21 -> 78994.127 | H39: =H3-H21 -> 56762.566 | I39: =I3-I21 -> 75526.613 | J39: =J3-J21 -> 92174.8 | K39: =K3-K21 -> 91019.027 | ... O39: =O3-O21 -> 104946.88
A40: EBIT | B40: Actual | C40: CO | D40: =D4-D22 -> 164895.72 | E40: =E4-E22 -> 65801.752 | F40: =F4-F22 -> 188601.58 | G40: =G4-G22 -> 128160.6 | H40: =H4-H22 -> 42352.119 | I40: =I4-I22 -> 162683.41 | J40: =J4-J22 -> 94286.545 | K40: =K4-K22 -> 78197.792 | ... O40: =O4-O22 -> 50640.48
A41: EBIT | B41: Actual | C41: VA | D41: =D5-D23 -> 513206.95 | E41: =E5-E23 -> 402186.57 | F41: =F5-F23 -> 58233.097 | G41: =G5-G23 -> 354798.15 | H41: =H5-H23 -> 500822.34 | I41: =I5-I23 -> 369148.44 | J41: =J5-J23 -> 177255.94 | K41: =K5-K23 -> 66708.096 | ... O41: =O5-O23 -> 201526.55
A42: EBIT | B42: Actual | C42: KS | D42: =D6-D24 -> 90746.945 | E42: =E6-E24 -> 443423.73 | F42: =F6-F24 -> 29300.049 | G42: =G6-G24 -> 342312.01 | H42: =H6-H24 -> 325697.39 | I42: =I6-I24 -> 46884.3 | J42: =J6-J24 -> 174146.94 | K42: =K6-K24 -> 154409.58 | ... O42: =O6-O24 -> 169381.13
A43: EBIT | B43: Actual | C43: FL | D43: =D7-D25 -> 281492.03 | E43: =E7-E25 -> 98521.201 | F43: =F7-F25 -> 398669.37 | G43: =G7-G25 -> 172665.93 | H43: =H7-H25 -> 41296.598 | I43: =I7-I25 -> 115891.07 | J43: =J7-J25 -> 138577.12 | K43: =K7-K25 -> 197811.59 | ... O43: =O7-O25 -> 217318.03
A44: EBIT | B44: Actual | C44: WA | D44: =D8-D26 -> 132716.47 | E44: =E8-E26 -> 47116.65 | F44: =F8-F26 -> 89671.158 | G44: =G8-G26 -> 49604.23 | H44: =H8-H26 -> 5634.5595 | I44: =I8-I26 -> 20122.181 | J44: =J8-J26 -> 43830.502 | K44: =K8-K26 -> 33021.744 | ... O44: =O8-O26 -> 36050.2
A45: EBIT | B45: Actual | C45: NY | D45: =D9-D27 -> 385570.31 | E45: =E9-E27 -> 682129.08 | F45: =F9-F27 -> 475410.84 | G45: =G9-G27 -> 828018.49 | H45: =H9-H27 -> 173567.42 | I45: =I9-I27 -> 7392.609 | J45: =J9-J27 -> 146294.72 | K45: =K9-K27 -> 175070.07 | ... O45: =O9-O27 -> 122595.06
A47: EBIT | B47: Plan | C47: MI | D47: =D11-D29 -> 86211.36 | E47: =E11-E29 -> 351715.93 | F47: =F11-F29 -> 29706.662 | G47: =G11-G29 -> 196076.25 | H47: =H11-H29 -> 97300.492 | I47: =I11-I29 -> 34647.497 | J47: =J11-J29 -> 87587.91 | K47: =K11-K29 -> 104145.84 | ... O47: =O11-O29 -> 74976.09
A48: EBIT | B48: Plan | C48: TX | D48: =D12-D30 -> 59364.236 | E48: =E12-E30 -> 269861.56 | F48: =F12-F30 -> 61121.822 | G48: =G12-G30 -> 92915.057 | H48: =H12-H30 -> 57694.344 | I48: =I12-I30 -> 29842.222 | J48: =J12-J30 -> 101821 | K48: =K12-K30 -> 69050.37 | ... O48: =O12-O30 -> 54708.03
A49: EBIT | B49: Plan | C49: CO | D49: =D13-D31 -> 33954.9 | E49: =E13-E31 -> 41317.936 | F49: =F13-F31 -> 79142.448 | G49: =G13-G31 -> 17947.59 | H49: =H13-H31 -> 19624.163 | I49: =I13-I31 -> 78990.372 | J49: =J13-J31 -> 40422.5 | K49: =K13-K31 -> 2372.91 | ... O49: =O13-O31 -> 18485.1
A50: EBIT | B50: Plan | C50: VA | D50: =D14-D32 -> 323113.82 | E50: =E14-E32 -> 123449 | F50: =F14-F32 -> 38516.068 | G50: =G14-G32 -> 250673.82 | H50: =H14-H32 -> 197800.8 | I50: =I14-I32 -> 10011.845 | J50: =J14-J32 -> 53648.205 | K50: =K14-K32 -> 63871.92 | ... O50: =O14-O32 -> 20294.28
... A54: EBIT | B54: Plan | C54: NY | D54: =D18-D36 -> 280354.36 | E54: =E18-E36 -> 458450.87 | F54: =F18-F36 -> 305506.51 | G54: =G18-G36 -> 633280.2 | H54: =H18-H36 -> 42237.064 | I54: =I18-I36 -> 175585.06 | J54: =J18-J36 -> 113141.6 | K54: =K18-K36 -> 17962.22 | ... O54: =O18-O36 -> 348816.39

Sheet PreviousYearData
A1: Category | B1: Exp | C1: State | D1: 2014 | E1: 2015 | F1: 2016 | G1: 2017 | H1: 2018 | I1: 2019 | J1: 2020 | K1: 2021
A2: Operations | B2: Exp | C2: MI | D2: 722972.8 | E2: 834359.04 | F2: 942550 | G2: 903716 | H2: 927065.6 | I2: 1346500 | J2: 1264337.6 | K2: 1408528
A3: Strategy | B3: Exp | C3: MI | D3: 684921.6 | E3: 1303686 | F3: 791742 | G3: 856152 | H3: 1448540 | I3: 1131060 | J3: 1784947.2 | K3: 1549380.8
A4: Finance | B4: Exp | C4: MI | D4: 608819.2 | E4: 1042948.8 | F4: 791742 | G4: 761024 | H4: 1158832 | I4: 1131060 | J4: 1859320 | K4: 1478954.4
A5: Commercial | B5: Exp | C5: MI | D5: 721006.4 | E5: 819807.3 | F5: 754040 | G5: 901258 | H5: 910897 | I5: 1077200 | J5: 1859320 | K5: 1056396
A6: HR | B6: Exp | C6: MI | D6: 1065433.6 | E6: 1199391.1 | F6: 490126 | G6: 1331792 | H6: 1332656.8 | I6: 700180 | J6: 669355.2 | K6: 1549380.8
A7: Operations | B7: Exp | C7: TX | D7: 698257.92 | E7: 650733.48 | F7: 545390.72 | G7: 872822.4 | H7: 723037.2 | I7: 779129.6 | J7: 922134.4 | K7: 1481154.4
A8: Strategy | B8: Exp | C8: TX | D8: 610975.68 | E8: 880404.12 | F8: 749912.24 | G8: 763719.6 | H8: 978226.8 | I8: 1071303.2 | J8: 1193350.4 | K8: 1211853.6
A9: Finance | B9: Exp | C9: TX | D9: 494599.36 | E9: 727290.36 | F9: 783999.16 | G9: 618249.2 | H9: 808100.4 | I9: 1119998.8 | J9: 1084864 | K9: 1077203.2
A10: Commercial | B10: Exp | C10: TX | D10: 669163.84 | E10: 765568.8 | F10: 579477.64 | G10: 836454.8 | H10: 850632 | I10: 827825.2 | J10: 922134.4 | K10: 1481154.4
A11: HR | B11: Exp | C11: TX | D11: 436411.2 | E11: 803847.24 | F11: 749912.24 | G11: 545514 | H11: 893163.6 | I11: 1071303.2 | J11: 1301836.8 | K11: 1481154.4
A12: Operations | B12: Exp | C12: CO | D12: 574760.06 | E12: 504589.41 | F12: 336599.2 | G12: 718450.08 | H12: 560654.9 | I12: 480856 | J12: 776291.4 | K12: 1038099.5
... A49: All Depts | B49: Rev | C49: NY | D49: 7372141.1 | E49: 9964342.4 | F49: 7755912.9 | G49: 8568497.3 | H49: 10227056 | I49: 12003198 | J49: 12897739 | K49: 13792451

Sheet HistoricalRevenue
A1: Category | B1: Exp | C1: State | D1: 2014 | E1: 2015 | F1: 2016 | G1: 2017 | H1: 2018 | I1: 2019 | J1: 2020 | K1: 2021
A2: Actual | B2: Rev | C2: MI | D2: 4183469 | E2: 5876217.3 | F2: 4335730 | G2: 5609651.6 | H2: 6240230.7 | I2: 6086180 | J2: 8478499.2 | K2: 7746904
A3: Actual | B3: Rev | C3: TX | D3: 3171254.7 | E3: 4134071.5 | F3: 4056343.5 | G3: 4000436 | H3: 4465818 | I3: 5502602.8 | J3: 6129481.6 | K3: 8079024
A4: Actual | B4: Rev | C4: CO | D4: 2801955.3 | E4: 3383717.2 | F4: 2398269.3 | G4: 3233025.4 | H4: 3693726.4 | I4: 3245778 | J4: 4931733.6 | K4: 5379242.8
A5: Actual | B5: Rev | C5: VA | D5: 4665733.6 | E5: 6335081.8 | F5: 5091824.6 | G5: 5832167 | H5: 6610520.2 | I5: 7398377.6 | J5: 8434607 | K5: 9784227.6
A6: Actual | B6: Rev | C6: KS | D6: 4843903.8 | E6: 6445935.3 | F6: 3968942.9 | G6: 6054879.7 | H6: 6733645.6 | I6: 5825971.2 | J6: 9641356.2 | K6: 7469382.6
A7: Actual | B7: Rev | C7: FL | D7: 5553061.1 | E7: 6574055 | F7: 4768300.5 | G7: 6458451.5 | H7: 7304505.6 | I7: 6386116.8 | J7: 10469791 | K7: 13828278
A8: Actual | B8: Rev | C8: WA | D8: 1085726.6 | E8: 1343508.7 | F8: 1126468 | G8: 1432555.9 | H8: 1478704.5 | I8: 1609240 | J8: 2073436.2 | K8: 2183932.8
A9: Actual | B9: Rev | C9: NY | D9: 7372141.1 | E9: 9964342.4 | F9: 7755912.9 | G9: 8568497.3 | H9: 10227056 | I9: 12003198 | J9: 12897739 | K9: 13792451
A11: Budget | B11: Rev | C11: MI | D11: 4141634.3 | E11: 6111265.9 | F11: 3945514.3 | G11: 5441362 | H11: 5803414.6 | I11: 6329627.2 | J11: 9156779.1 | K11: 7437027.8
A12: Budget | B12: Rev | C12: TX | D12: 3266392.4 | E12: 3844686.5 | F12: 4218597.2 | G12: 4240462.2 | H12: 4019236.2 | I12: 5117420.6 | J12: 5761712.7 | K12: 7594282.6
A13: Budget | B13: Rev | C13: CO | D13: 3054131.3 | E13: 3113019.8 | F13: 2326321.2 | G13: 3006713.6 | H13: 3324353.8 | I13: 3440524.7 | J13: 4685146.9 | K13: 5110280.6
... A18: Budget | B18: Rev | C18: NY | D18: 7298419.6 | E18: 9266838.5 | F18: 6980321.6 | G18: 9082607.1 | H18: 9613432.5 | I18: 11042943 | J18: 13929558 | K18: 13516602

Sheet Debtors
A1: Description | B1: State | C1: Month | D1: 0-30 | E1: 31-60 | F1: 61-90 | G1: 90+
A2: Debtors | B2: MI | C2: 44562 | D2: 809370 | E2: 687964.5 | F2: 309584.02 | G2: 139312.81
A3: Debtors | B3: TX | C3: 44562 | D3: 616285 | E3: 511516.55 | F3: 260873.44 | G3: 133045.45
A4: Debtors | B4: CO | C4: 44562 | D4: 489325 | E4: 396353.25 | F4: 225921.35 | G4: 128775.17
A5: Debtors | B5: VA | C5: 44562 | D5: 854335 | E5: 734728.1 | F5: 308585.8 | G5: 129606.04
A6: Debtors | B6: KS | C6: 44562 | D6: 870205 | E6: 757078.35 | F6: 295260.56 | G6: 115151.62
A7: Debtors | B7: FL | C7: 44562 | D7: 968070 | E7: 851901.6 | F7: 306684.58 | G7: 110406.45
A8: Debtors | B8: WA | C8: 44562 | D8: 227470 | E8: 202448.3 | F8: 66807.939 | G8: 22046.62
A9: Debtors | B9: NY | C9: 44562 | D9: 1375400 | E9: 1141582 | F9: 582206.82 | G9: 296925.48
A10: Debtors | B10: MI | C10: 44593 | D10: 866025.9 | E10: 749881.31 | F10: 297200.66 | G10: 139312.81
A11: Debtors | B11: TX | C11: 44593 | D11: 634773.55 | E11: 516631.72 | F11: 268699.64 | G11: 127723.64
A12: Debtors | B12: CO | C12: 44593 | D12: 538257.5 | E12: 380499.12 | F12: 246254.27 | G12: 141652.69
A13: Debtors | B13: VA | C13: 44593 | D13: 871421.7 | E13: 800853.63 | F13: 324015.09 | G13: 123125.73
... A98: Debtors | B98: MI | C98: 44896 | D98: 556508.24 | E98: 486463 | F98: 194618.88 | G98: 97195.762

Sheet HR & Campaign
A1: Type | B1: State | C1: Jan | D1: Feb | E1: Mar | F1: Apr | G1: May | H1: Jun | I1: Jul | J1: Aug | K1: Sep | L1: Oct | M1: Nov | N1: Dec
A2: Termination | B2: MI | C2: -6 | D2: -5 | E2: -4 | F2: -3 | G2: -3 | H2: -1 | I2: -4 | J2: -1 | K2: -3 | L2: -2 | M2: -1 | N2: -7
A3: New Hires | B3: MI | C3: 4 | D3: 5 | E3: 6 | F3: 2 | G3: 3 | H3: 4 | I3: 7 | J3: 5 | K3: 4 | L3: 6 | M3: 6 | N3: 4
A4: Termination | B4: TX | C4: -8 | D4: -3 | E4: -3 | F4: -2 | G4: -3 | H4: -2 | I4: -6 | J4: 1 | K4: 1 | L4: 2 | M4: -1 | N4: -6
A5: New Hires | B5: TX | C5: 6 | D5: 7 | E5: 3 | F5: 3 | G5: 5 | H5: 4 | I5: 10 | J5: 11 | K5: 7 | L5: 6 | M5: 8 | N5: 1
A6: Termination | B6: CO | C6: -7 | D6: -3 | E6: -3 | F6: -3 | G6: -2 | H6: -3 | I6: -3 | J6: -1 | K6: -1 | L6: 0 | M6: 0 | N6: -6
A7: New Hires | B7: CO | C7: 5 | D7: 11 | E7: 4 | F7: 5 | G7: 3 | H7: 6 | I7: 9 | J7: 14 | K7: 7 | L7: 9 | M7: 5 | N7: 1
A8: Termination | B8: VA | C8: -4 | D8: -3 | E8: -4 | F8: -3 | G8: -3 | H8: -3 | I8: -2 | J8: 1 | K8: -2 | L8: 1 | M8: -1 | N8: -6
A9: New Hires | B9: VA | C9: 4 | D9: 11 | E9: 3 | F9: 3 | G9: 3 | H9: 8 | I9: 7 | J9: 15 | K9: 7 | L9: 7 | M9: 7 | N9: 1
A10: Termination | B10: KS | C10: -2 | D10: -3 | E10: -4 | F10: -3 | G10: -5 | H10: -3 | I10: 0 | J10: 1 | K10: 0 | L10: -1 | M10: -2 | N10: -7
A11: New Hires | B11: KS | C11: 6 | D11: 14 | E11: 2 | F11: 5 | G11: 5 | H11: 8 | I11: 9 | J11: 12 | K11: 4 | L11: 9 | M11: 8 | N11: -1
A12: Termination | B12: FL | C12: -3 | D12: -3 | E12: -3 | F12: -2 | G12: -6 | H12: -3 | I12: 0 | J12: 1 | K12: -1 | L12: 0 | M12: -3 | N12: -7
A13: New Hires | B13: FL | C13: 7 | D13: 9 | E13: 1 | F13: 4 | G13: 8 | H13: 6 | I13: 11 | J13: 12 | K13: 5 | L13: 6 | M13: 10 | N13: -3
... A17: New Hires | B17: NY | C17: 8 | D17: 9 | E17: 2 | F17: 3 | G17: 17 | H17: 8 | I17: 11 | J17: 12 | K17: 6 | L17: 6 | M17: 21 | N17: -2
A21: Type | B21: State | C21: FACEBOOK | D21: INSTAGRAM | E21: TIKTOK
A22: Campaigns | B22: MI | C22: 41 | D22: 29 | E22: 40
A23: Campaigns | B23: TX | C23: 41 | D23: 41 | E23: 42
A24: Campaigns | B24: CO | C24: 40 | D24: 41 | E24: 44
A25: Campaigns | B25: VA | C25: 52 | D25: 40 | E25: 49
A26: Campaigns | B26: KS | C26: 35 | D26: 25 | E26: 39
A27: Campaigns | B27: FL | C27: 38 | D27: 36 | E27: 39
A28: Campaigns | B28: WA | C28: 41 | D28: 32 | E28: 36
A29: Campaigns | B29: NY | C29: 44 | D29: 40 | E29: 37

Sheet Satisfaction
A1: Score | B1: State | C1: 2019 | D1: 2020 | E1: 2021 | F1: 2022
A2: Poor | B2: NY | C2: 0.5 | D2: 0.6 | E2: 0.6 | F2: 0.6
A3: Fair | B3: NY | C3: 0.1 | D3: 0.15 | E3: 0.15 | F3: 0.15
A4: Good | B4: NY | C4: 0.2 | D4: 0.15 | E4: 0.15 | F4: 0.15
A5: Excellent | B5: NY | C5: 0.2 | D5: 0.1 | E5: 0.1 | F5: 0.1
A6: Value | B6: NY | C6: 0.7 | D6: 0.86 | E6: 0.95 | F6: 0.85
A7: Target | B7: NY | C7: 0.9 | D7: 0.9 | E7: 0.9 | F7: 0.9
A8: Poor | B8: TX | C8: 0.5 | D8: 0.6 | E8: 0.6 | F8: 0.6
A9: Fair | B9: TX | C9: 0.1 | D9: 0.15 | E9: 0.15 | F9: 0.15
A10: Good | B10: TX | C10: 0.2 | D10: 0.15 | E10: 0.15 | F10: 0.15
A11: Excellent | B11: TX | C11: 0.2 | D11: 0.1 | E11: 0.1 | F11: 0.1
A12: Value | B12: TX | C12: 0.8 | D12: 0.85 | E12: 0.87 | F12: 0.9
... A49: Target | B49: KS | C49: 0.95 | D49: 0.95 | E49: 0.95 | F49: 0.95

Sheet Calculations
A1: Total Expense for the Current Year
A2: Type | B2: State | C2: Active Plan | D2: Jan | E2: Feb | F2: Mar | G2: Apr | H2: May | I2: Jun | J2: Jul | K2: Aug | L2: Sep | M2: Oct | N2: Nov | O2: Dec
A3: Revenue | B3: =CurrentYearData!$S$2 -> WA | C3: Actual | D3: =SUMIFS(CurrentYearData!D$2:D$54, CurrentYearData!$A$2:$A$54, $A3, CurrentYearData!$B$2:$B$54,$C3, CurrentYearData!$C$2:$C$54, $B3) -> 233404 | E3: =SUMIFS(CurrentYearData!E$2:E$54, CurrentYearData!$A$2:$A$54, $A3, CurrentYearData!$B$2:$B$54,$C3, CurrentYearData!$C$2:$C$54, $B3) -> 142968 | F3: =SUMIFS(CurrentYearData!F$2:F$54, CurrentYearData!$A$2:$A$54, $A3, CurrentYearData!$B$2:$B$54,$C3, CurrentYearData!$C$2:$C$54, $B3) -> 190026 | G3: =SUMIFS(CurrentYearData!G$2:G$54, CurrentYearData!$A$2:$A$54, $A3, CurrentYearData!$B$2:$B$54,$C3, CurrentYearData!$C$2:$C$54, $B3) -> 169802 | H3: =SUMIFS(CurrentYearData!H$2:H$54, CurrentYearData!$A$2:$A$54, $A3, CurrentYearData!$B$2:$B$54,$C3, CurrentYearData!$C$2:$C$54, $B3) -> 188350 | I3: =SUMIFS(CurrentYearData!I$2:I$54, CurrentYearData!$A$2:$A$54, $A3, CurrentYearData!$B$2:$B$54,$C3, CurrentYearData!$C$2:$C$54, $B3) -> 178272 | J3: =SUMIFS(CurrentYearData!J$2:J$54, CurrentYearData!$A$2:$A$54, $A3, CurrentYearData!$B$2:$B$54,$C3, CurrentYearData!$C$2:$C$54, $B3) -> 197800 | K3: =SUMIFS(CurrentYearData!K$2:K$54, CurrentYearData!$A$2:$A$54, $A3, CurrentYearData!$B$2:$B$54,$C3, CurrentYearData!$C$2:$C$54, $B3) -> 193200 | ... O3: =SUMIFS(CurrentYearData!O$2:O$54, CurrentYearData!$A$2:$A$54, $A3, CurrentYearData!$B$2:$B$54,$C3, CurrentYearData!$C$2:$C$54, $B3) -> 156400
A4: Revenue | B4: =CurrentYearData!$S$2 -> WA | C4: Plan | D4: =SUMIFS(CurrentYearData!D$2:D$54, CurrentYearData!$A$2:$A$54, $A4, CurrentYearData!$B$2:$B$54,$C4, CurrentYearData!$C$2:$C$54, $B4) -> 227514.62 | E4: =SUMIFS(CurrentYearData!E$2:E$54, CurrentYearData!$A$2:$A$54, $A4, CurrentYearData!$B$2:$B$54,$C4, CurrentYearData!$C$2:$C$54, $B4) -> 130203 | F4: =SUMIFS(CurrentYearData!F$2:F$54, CurrentYearData!$A$2:$A$54, $A4, CurrentYearData!$B$2:$B$54,$C4, CurrentYearData!$C$2:$C$54, $B4) -> 159528 | G4: =SUMIFS(CurrentYearData!G$2:G$54, CurrentYearData!$A$2:$A$54, $A4, CurrentYearData!$B$2:$B$54,$C4, CurrentYearData!$C$2:$C$54, $B4) -> 188725.72 | H4: =SUMIFS(CurrentYearData!H$2:H$54, CurrentYearData!$A$2:$A$54, $A4, CurrentYearData!$B$2:$B$54,$C4, CurrentYearData!$C$2:$C$54, $B4) -> 113141.6 | I4: =SUMIFS(CurrentYearData!I$2:I$54, CurrentYearData!$A$2:$A$54, $A4, CurrentYearData!$B$2:$B$54,$C4, CurrentYearData!$C$2:$C$54, $B4) -> 117072.76 | J4: =SUMIFS(CurrentYearData!J$2:J$54, CurrentYearData!$A$2:$A$54, $A4, CurrentYearData!$B$2:$B$54,$C4, CurrentYearData!$C$2:$C$54, $B4) -> 192809 | K4: =SUMIFS(CurrentYearData!K$2:K$54, CurrentYearData!$A$2:$A$54, $A4, CurrentYearData!$B$2:$B$54,$C4, CurrentYearData!$C$2:$C$54, $B4) -> 175950 | ... O4: =SUMIFS(CurrentYearData!O$2:O$54, CurrentYearData!$A$2:$A$54, $A4, CurrentYearData!$B$2:$B$54,$C4, CurrentYearData!$C$2:$C$54, $B4) -> 119462
A5: Expense | B5: =CurrentYearData!$S$2 -> WA | C5: Actual | D5: =SUMIFS(CurrentYearData!D$2:D$54, CurrentYearData!$A$2:$A$54, $A5, CurrentYearData!$B$2:$B$54,$C5, CurrentYearData!$C$2:$C$54, $B5) -> 100687.53 | E5: =SUMIFS(CurrentYearData!E$2:E$54, CurrentYearData!$A$2:$A$54, $A5, CurrentYearData!$B$2:$B$54,$C5, CurrentYearData!$C$2:$C$54, $B5) -> 95851.35 | F5: =SUMIFS(CurrentYearData!F$2:F$54, CurrentYearData!$A$2:$A$54, $A5, CurrentYearData!$B$2:$B$54,$C5, CurrentYearData!$C$2:$C$54, $B5) -> 100354.84 | G5: =SUMIFS(CurrentYearData!G$2:G$54, CurrentYearData!$A$2:$A$54, $A5, CurrentYearData!$B$2:$B$54,$C5, CurrentYearData!$C$2:$C$54, $B5) -> 120197.77 | H5: =SUMIFS(CurrentYearData!H$2:H$54, CurrentYearData!$A$2:$A$54, $A5, CurrentYearData!$B$2:$B$54,$C5, CurrentYearData!$C$2:$C$54, $B5) -> 182715.44 | I5: =SUMIFS(CurrentYearData!I$2:I$54, CurrentYearData!$A$2:$A$54, $A5, CurrentYearData!$B$2:$B$54,$C5, CurrentYearData!$C$2:$C$54, $B5) -> 158149.82 | J5: =SUMIFS(CurrentYearData!J$2:J$54, CurrentYearData!$A$2:$A$54, $A5, CurrentYearData!$B$2:$B$54,$C5, CurrentYearData!$C$2:$C$54, $B5) -> 153969.5 | K5: =SUMIFS(CurrentYearData!K$2:K$54, CurrentYearData!$A$2:$A$54, $A5, CurrentYearData!$B$2:$B$54,$C5, CurrentYearData!$C$2:$C$54, $B5) -> 160178.26 | ... O5: =SUMIFS(CurrentYearData!O$2:O$54, CurrentYearData!$A$2:$A$54, $A5, CurrentYearData!$B$2:$B$54,$C5, CurrentYearData!$C$2:$C$54, $B5) -> 120349.8
A6: Expense | B6: =CurrentYearData!$S$2 -> WA | C6: Plan | D6: =SUMIFS(CurrentYearData!D$2:D$54, CurrentYearData!$A$2:$A$54, $A6, CurrentYearData!$B$2:$B$54,$C6, CurrentYearData!$C$2:$C$54, $B6) -> 143839.33 | E6: =SUMIFS(CurrentYearData!E$2:E$54, CurrentYearData!$A$2:$A$54, $A6, CurrentYearData!$B$2:$B$54,$C6, CurrentYearData!$C$2:$C$54, $B6) -> 116930.5 | F6: =SUMIFS(CurrentYearData!F$2:F$54, CurrentYearData!$A$2:$A$54, $A6, CurrentYearData!$B$2:$B$54,$C6, CurrentYearData!$C$2:$C$54, $B6) -> 143364.06 | G6: =SUMIFS(CurrentYearData!G$2:G$54, CurrentYearData!$A$2:$A$54, $A6, CurrentYearData!$B$2:$B$54,$C6, CurrentYearData!$C$2:$C$54, $B6) -> 143139.67 | H6: =SUMIFS(CurrentYearData!H$2:H$54, CurrentYearData!$A$2:$A$54, $A6, CurrentYearData!$B$2:$B$54,$C6, CurrentYearData!$C$2:$C$54, $B6) -> 108164.91 | I6: =SUMIFS(CurrentYearData!I$2:I$54, CurrentYearData!$A$2:$A$54, $A6, CurrentYearData!$B$2:$B$54,$C6, CurrentYearData!$C$2:$C$54, $B6) -> 83071.17 | J6: =SUMIFS(CurrentYearData!J$2:J$54, CurrentYearData!$A$2:$A$54, $A6, CurrentYearData!$B$2:$B$54,$C6, CurrentYearData!$C$2:$C$54, $B6) -> 158065.2 | K6: =SUMIFS(CurrentYearData!K$2:K$54, CurrentYearData!$A$2:$A$54, $A6, CurrentYearData!$B$2:$B$54,$C6, CurrentYearData!$C$2:$C$54, $B6) -> 163012.5 | ... O6: =SUMIFS(CurrentYearData!O$2:O$54, CurrentYearData!$A$2:$A$54, $A6, CurrentYearData!$B$2:$B$54,$C6, CurrentYearData!$C$2:$C$54, $B6) -> 106501.5
A7: EBIT | B7: =CurrentYearData!$S$2 -> WA | C7: Actual | D7: =SUMIFS(CurrentYearData!D$2:D$54, CurrentYearData!$A$2:$A$54, $A7, CurrentYearData!$B$2:$B$54,$C7, CurrentYearData!$C$2:$C$54, $B7) -> 132716.47 | E7: =SUMIFS(CurrentYearData!E$2:E$54, CurrentYearData!$A$2:$A$54, $A7, CurrentYearData!$B$2:$B$54,$C7, CurrentYearData!$C$2:$C$54, $B7) -> 47116.65 | F7: =SUMIFS(CurrentYearData!F$2:F$54, CurrentYearData!$A$2:$A$54, $A7, CurrentYearData!$B$2:$B$54,$C7, CurrentYearData!$C$2:$C$54, $B7) -> 89671.158 | G7: =SUMIFS(CurrentYearData!G$2:G$54, CurrentYearData!$A$2:$A$54, $A7, CurrentYearData!$B$2:$B$54,$C7, CurrentYearData!$C$2:$C$54, $B7) -> 49604.23 | H7: =SUMIFS(CurrentYearData!H$2:H$54, CurrentYearData!$A$2:$A$54, $A7, CurrentYearData!$B$2:$B$54,$C7, CurrentYearData!$C$2:$C$54, $B7) -> 5634.5595 | I7: =SUMIFS(CurrentYearData!I$2:I$54, CurrentYearData!$A$2:$A$54, $A7, CurrentYearData!$B$2:$B$54,$C7, CurrentYearData!$C$2:$C$54, $B7) -> 20122.181 | J7: =SUMIFS(CurrentYearData!J$2:J$54, CurrentYearData!$A$2:$A$54, $A7, CurrentYearData!$B$2:$B$54,$C7, CurrentYearData!$C$2:$C$54, $B7) -> 43830.502 | K7: =SUMIFS(CurrentYearData!K$2:K$54, CurrentYearData!$A$2:$A$54, $A7, CurrentYearData!$B$2:$B$54,$C7, CurrentYearData!$C$2:$C$54, $B7) -> 33021.744 | ... O7: =SUMIFS(CurrentYearData!O$2:O$54, CurrentYearData!$A$2:$A$54, $A7, CurrentYearData!$B$2:$B$54,$C7, CurrentYearData!$C$2:$C$54, $B7) -> 36050.2
A8: EBIT | B8: =CurrentYearData!$S$2 -> WA | C8: Plan | D8: =SUMIFS(CurrentYearData!D$2:D$54, CurrentYearData!$A$2:$A$54, $A8, CurrentYearData!$B$2:$B$54,$C8, CurrentYearData!$C$2:$C$54, $B8) -> 83675.288 | E8: =SUMIFS(CurrentYearData!E$2:E$54, CurrentYearData!$A$2:$A$54, $A8, CurrentYearData!$B$2:$B$54,$C8, CurrentYearData!$C$2:$C$54, $B8) -> 13272.5 | F8: =SUMIFS(CurrentYearData!F$2:F$54, CurrentYearData!$A$2:$A$54, $A8, CurrentYearData!$B$2:$B$54,$C8, CurrentYearData!$C$2:$C$54, $B8) -> 16163.94 | G8: =SUMIFS(CurrentYearData!G$2:G$54, CurrentYearData!$A$2:$A$54, $A8, CurrentYearData!$B$2:$B$54,$C8, CurrentYearData!$C$2:$C$54, $B8) -> 45586.048 | H8: =SUMIFS(CurrentYearData!H$2:H$54, CurrentYearData!$A$2:$A$54, $A8, CurrentYearData!$B$2:$B$54,$C8, CurrentYearData!$C$2:$C$54, $B8) -> 4976.685 | I8: =SUMIFS(CurrentYearData!I$2:I$54, CurrentYearData!$A$2:$A$54, $A8, CurrentYearData!$B$2:$B$54,$C8, CurrentYearData!$C$2:$C$54, $B8) -> 34001.59 | J8: =SUMIFS(CurrentYearData!J$2:J$54, CurrentYearData!$A$2:$A$54, $A8, CurrentYearData!$B$2:$B$54,$C8, CurrentYearData!$C$2:$C$54, $B8) -> 34743.8 | K8: =SUMIFS(CurrentYearData!K$2:K$54, CurrentYearData!$A$2:$A$54, $A8, CurrentYearData!$B$2:$B$54,$C8, CurrentYearData!$C$2:$C$54, $B8) -> 12937.5 | ... O8: =SUMIFS(CurrentYearData!O$2:O$54, CurrentYearData!$A$2:$A$54, $A8, CurrentYearData!$B$2:$B$54,$C8, CurrentYearData!$C$2:$C$54, $B8) -> 12960.5
A10: =CurrentYearData!R13 -> Revenue | B10: =CurrentYearData!$S$2 -> WA | C10: Actual | D10: =SUMIFS(CurrentYearData!D$2:D$54, CurrentYearData!$A$2:$A$54, $A10, CurrentYearData!$B$2:$B$54,$C10, CurrentYearData!$C$2:$C$54, $B10) -> 233404 | E10: =SUMIFS(CurrentYearData!E$2:E$54, CurrentYearData!$A$2:$A$54, $A10, CurrentYearData!$B$2:$B$54,$C10, CurrentYearData!$C$2:$C$54, $B10) -> 142968 | F10: =SUMIFS(CurrentYearData!F$2:F$54, CurrentYearData!$A$2:$A$54, $A10, CurrentYearData!$B$2:$B$54,$C10, CurrentYearData!$C$2:$C$54, $B10) -> 190026 | G10: =SUMIFS(CurrentYearData!G$2:G$54, CurrentYearData!$A$2:$A$54, $A10, CurrentYearData!$B$2:$B$54,$C10, CurrentYearData!$C$2:$C$54, $B10) -> 169802 | H10: =SUMIFS(CurrentYearData!H$2:H$54, CurrentYearData!$A$2:$A$54, $A10, CurrentYearData!$B$2:$B$54,$C10, CurrentYearData!$C$2:$C$54, $B10) -> 188350 | I10: =SUMIFS(CurrentYearData!I$2:I$54, CurrentYearData!$A$2:$A$54, $A10, CurrentYearData!$B$2:$B$54,$C10, CurrentYearData!$C$2:$C$54, $B10) -> 178272 | J10: =SUMIFS(CurrentYearData!J$2:J$54, CurrentYearData!$A$2:$A$54, $A10, CurrentYearData!$B$2:$B$54,$C10, CurrentYearData!$C$2:$C$54, $B10) -> 197800 | K10: =SUMIFS(CurrentYearData!K$2:K$54, CurrentYearData!$A$2:$A$54, $A10, CurrentYearData!$B$2:$B$54,$C10, CurrentYearData!$C$2:$C$54, $B10) -> 193200 | ... O10: =SUMIFS(CurrentYearData!O$2:O$54, CurrentYearData!$A$2:$A$54, $A10, CurrentYearData!$B$2:$B$54,$C10, CurrentYearData!$C$2:$C$54, $B10) -> 156400
A11: =CurrentYearData!R13 -> Revenue | B11: =CurrentYearData!$S$2 -> WA | C11: Plan | D11: =SUMIFS(CurrentYearData!D$2:D$54, CurrentYearData!$A$2:$A$54, $A11, CurrentYearData!$B$2:$B$54,$C11, CurrentYearData!$C$2:$C$54, $B11) -> 227514.62 | E11: =SUMIFS(CurrentYearData!E$2:E$54, CurrentYearData!$A$2:$A$54, $A11, CurrentYearData!$B$2:$B$54,$C11, CurrentYearData!$C$2:$C$54, $B11) -> 130203 | F11: =SUMIFS(CurrentYearData!F$2:F$54, CurrentYearData!$A$2:$A$54, $A11, CurrentYearData!$B$2:$B$54,$C11, CurrentYearData!$C$2:$C$54, $B11) -> 159528 | G11: =SUMIFS(CurrentYearData!G$2:G$54, CurrentYearData!$A$2:$A$54, $A11, CurrentYearData!$B$2:$B$54,$C11, CurrentYearData!$C$2:$C$54, $B11) -> 188725.72 | H11: =SUMIFS(CurrentYearData!H$2:H$54, CurrentYearData!$A$2:$A$54, $A11, CurrentYearData!$B$2:$B$54,$C11, CurrentYearData!$C$2:$C$54, $B11) -> 113141.6 | I11: =SUMIFS(CurrentYearData!I$2:I$54, CurrentYearData!$A$2:$A$54, $A11, CurrentYearData!$B$2:$B$54,$C11, CurrentYearData!$C$2:$C$54, $B11) -> 117072.76 | J11: =SUMIFS(CurrentYearData!J$2:J$54, CurrentYearData!$A$2:$A$54, $A11, CurrentYearData!$B$2:$B$54,$C11, CurrentYearData!$C$2:$C$54, $B11) -> 192809 | K11: =SUMIFS(CurrentYearData!K$2:K$54, CurrentYearData!$A$2:$A$54, $A11, CurrentYearData!$B$2:$B$54,$C11, CurrentYearData!$C$2:$C$54, $B11) -> 175950 | ... O11: =SUMIFS(CurrentYearData!O$2:O$54, CurrentYearData!$A$2:$A$54, $A11, CurrentYearData!$B$2:$B$54,$C11, CurrentYearData!$C$2:$C$54, $B11) -> 119462
A14: New Hires & Terminations
A15: Type | B15: State | D15: Jan | E15: Feb | F15: Mar | G15: Apr | H15: May | I15: Jun | J15: Jul | K15: Aug | L15: Sep | M15: Oct | N15: Nov | O15: Dec
A16: Termination | B16: =CurrentYearData!$S$2 -> WA | D16: =SUMIFS('HR & Campaign'!C$2:C$17, 'HR & Campaign'!$A$2:$A$17,Calculations!$A16,'HR & Campaign'!$B$2:$B$17,Calculations!$B16) -> -4 | E16: =SUMIFS('HR & Campaign'!D$2:D$17, 'HR & Campaign'!$A$2:$A$17,Calculations!$A16,'HR & Campaign'!$B$2:$B$17,Calculations!$B16) -> -5 | F16: =SUMIFS('HR & Campaign'!E$2:E$17, 'HR & Campaign'!$A$2:$A$17,Calculations!$A16,'HR & Campaign'!$B$2:$B$17,Calculations!$B16) -> -5 | G16: =SUMIFS('HR & Campaign'!F$2:F$17, 'HR & Campaign'!$A$2:$A$17,Calculations!$A16,'HR & Campaign'!$B$2:$B$17,Calculations!$B16) -> -3 | H16: =SUMIFS('HR & Campaign'!G$2:G$17, 'HR & Campaign'!$A$2:$A$17,Calculations!$A16,'HR & Campaign'!$B$2:$B$17,Calculations!$B16) -> -8 | I16: =SUMIFS('HR & Campaign'!H$2:H$17, 'HR & Campaign'!$A$2:$A$17,Calculations!$A16,'HR & Campaign'!$B$2:$B$17,Calculations!$B16) -> -3 | J16: =SUMIFS('HR & Campaign'!I$2:I$17, 'HR & Campaign'!$A$2:$A$17,Calculations!$A16,'HR & Campaign'!$B$2:$B$17,Calculations!$B16) -> 0 | K16: =SUMIFS('HR & Campaign'!J$2:J$17, 'HR & Campaign'!$A$2:$A$17,Calculations!$A16,'HR & Campaign'!$B$2:$B$17,Calculations!$B16) -> -1 | ... O16: =SUMIFS('HR & Campaign'!N$2:N$17, 'HR & Campaign'!$A$2:$A$17,Calculations!$A16,'HR & Campaign'!$B$2:$B$17,Calculations!$B16) -> -8
A17: New Hires | B17: =CurrentYearData!$S$2 -> WA | D17: =SUMIFS('HR & Campaign'!C$2:C$17, 'HR & Campaign'!$A$2:$A$17,Calculations!$A17,'HR & Campaign'!$B$2:$B$17,Calculations!$B17) -> 5 | E17: =SUMIFS('HR & Campaign'!D$2:D$17, 'HR & Campaign'!$A$2:$A$17,Calculations!$A17,'HR & Campaign'!$B$2:$B$17,Calculations!$B17) -> 9 | F17: =SUMIFS('HR & Campaign'!E$2:E$17, 'HR & Campaign'!$A$2:$A$17,Calculations!$A17,'HR & Campaign'!$B$2:$B$17,Calculations!$B17) -> 2 | G17: =SUMIFS('HR & Campaign'!F$2:F$17, 'HR & Campaign'!$A$2:$A$17,Calculations!$A17,'HR & Campaign'!$B$2:$B$17,Calculations!$B17) -> 3 | H17: =SUMIFS('HR & Campaign'!G$2:G$17, 'HR & Campaign'!$A$2:$A$17,Calculations!$A17,'HR & Campaign'!$B$2:$B$17,Calculations!$B17) -> 12 | I17: =SUMIFS('HR & Campaign'!H$2:H$17, 'HR & Campaign'!$A$2:$A$17,Calculations!$A17,'HR & Campaign'!$B$2:$B$17,Calculations!$B17) -> 6 | J17: =SUMIFS('HR & Campaign'!I$2:I$17, 'HR & Campaign'!$A$2:$A$17,Calculations!$A17,'HR & Campaign'!$B$2:$B$17,Calculations!$B17) -> 9 | K17: =SUMIFS('HR & Campaign'!J$2:J$17, 'HR & Campaign'!$A$2:$A$17,Calculations!$A17,'HR & Campaign'!$B$2:$B$17,Calculations!$B17) -> 13 | ... O17: =SUMIFS('HR & Campaign'!N$2:N$17, 'HR & Campaign'!$A$2:$A$17,Calculations!$A17,'HR & Campaign'!$B$2:$B$17,Calculations!$B17) -> -2
A20: Expenses Trend Over Time
A21: Previous Year Data | B21: State | C21: =PreviousYearData!D1 -> 2014 | D21: =PreviousYearData!E1 -> 2015 | E21: =PreviousYearData!F1 -> 2016 | F21: =PreviousYearData!G1 -> 2017 | G21: =PreviousYearData!H1 -> 2018 | H21: =PreviousYearData!I1 -> 2019 | I21: =PreviousYearData!J1 -> 2020 | J21: =PreviousYearData!K1 -> 2021
A22: Operations | B22: =CurrentYearData!$S$2 -> WA | C22: =SUMIFS(PreviousYearData!D$2:D$49, PreviousYearData!$A$2:$A$49, Calculations!$A22, PreviousYearData!$C$2:$C$49, Calculations!$B22) -> 241272.58 | D22: =SUMIFS(PreviousYearData!E$2:E$49, PreviousYearData!$A$2:$A$49, Calculations!$A22, PreviousYearData!$C$2:$C$49, Calculations!$B22) -> 215468.37 | E22: =SUMIFS(PreviousYearData!F$2:F$49, PreviousYearData!$A$2:$A$49, Calculations!$A22, PreviousYearData!$C$2:$C$49, Calculations!$B22) -> 158100.77 | F22: =SUMIFS(PreviousYearData!G$2:G$49, PreviousYearData!$A$2:$A$49, Calculations!$A22, PreviousYearData!$C$2:$C$49, Calculations!$B22) -> 301590.72 | G22: =SUMIFS(PreviousYearData!H$2:H$49, PreviousYearData!$A$2:$A$49, Calculations!$A22, PreviousYearData!$C$2:$C$49, Calculations!$B22) -> 239409.3 | H22: =SUMIFS(PreviousYearData!I$2:I$49, PreviousYearData!$A$2:$A$49, Calculations!$A22, PreviousYearData!$C$2:$C$49, Calculations!$B22) -> 225858.24 | I22: =SUMIFS(PreviousYearData!J$2:J$49, PreviousYearData!$A$2:$A$49, Calculations!$A22, PreviousYearData!$C$2:$C$49, Calculations!$B22) -> 320440.14 | J22: =SUMIFS(PreviousYearData!K$2:K$49, PreviousYearData!$A$2:$A$49, Calculations!$A22, PreviousYearData!$C$2:$C$49, Calculations!$B22) -> 428986.8
A23: Strategy | B23: =CurrentYearData!$S$2 -> WA | C23: =SUMIFS(PreviousYearData!D$2:D$49, PreviousYearData!$A$2:$A$49, Calculations!$A23, PreviousYearData!$C$2:$C$49, Calculations!$B23) -> 211113.5 | D23: =SUMIFS(PreviousYearData!E$2:E$49, PreviousYearData!$A$2:$A$49, Calculations!$A23, PreviousYearData!$C$2:$C$49, Calculations!$B23) -> 291516.03 | E23: =SUMIFS(PreviousYearData!F$2:F$49, PreviousYearData!$A$2:$A$49, Calculations!$A23, PreviousYearData!$C$2:$C$49, Calculations!$B23) -> 217388.56 | F23: =SUMIFS(PreviousYearData!G$2:G$49, PreviousYearData!$A$2:$A$49, Calculations!$A23, PreviousYearData!$C$2:$C$49, Calculations!$B23) -> 263891.88 | G23: =SUMIFS(PreviousYearData!H$2:H$49, PreviousYearData!$A$2:$A$49, Calculations!$A23, PreviousYearData!$C$2:$C$49, Calculations!$B23) -> 323906.7 | H23: =SUMIFS(PreviousYearData!I$2:I$49, PreviousYearData!$A$2:$A$49, Calculations!$A23, PreviousYearData!$C$2:$C$49, Calculations!$B23) -> 310555.08 | I23: =SUMIFS(PreviousYearData!J$2:J$49, PreviousYearData!$A$2:$A$49, Calculations!$A23, PreviousYearData!$C$2:$C$49, Calculations!$B23) -> 414687.24 | J23: =SUMIFS(PreviousYearData!K$2:K$49, PreviousYearData!$A$2:$A$49, Calculations!$A23, PreviousYearData!$C$2:$C$49, Calculations!$B23) -> 350989.2
A24: Finance | B24: =CurrentYearData!$S$2 -> WA | C24: =SUMIFS(PreviousYearData!D$2:D$49, PreviousYearData!$A$2:$A$49, Calculations!$A24, PreviousYearData!$C$2:$C$49, Calculations!$B24) -> 170901.41 | D24: =SUMIFS(PreviousYearData!E$2:E$49, PreviousYearData!$A$2:$A$49, Calculations!$A24, PreviousYearData!$C$2:$C$49, Calculations!$B24) -> 240817.59 | E24: =SUMIFS(PreviousYearData!F$2:F$49, PreviousYearData!$A$2:$A$49, Calculations!$A24, PreviousYearData!$C$2:$C$49, Calculations!$B24) -> 227269.85 | F24: =SUMIFS(PreviousYearData!G$2:G$49, PreviousYearData!$A$2:$A$49, Calculations!$A24, PreviousYearData!$C$2:$C$49, Calculations!$B24) -> 213626.76 | G24: =SUMIFS(PreviousYearData!H$2:H$49, PreviousYearData!$A$2:$A$49, Calculations!$A24, PreviousYearData!$C$2:$C$49, Calculations!$B24) -> 267575.1 | H24: =SUMIFS(PreviousYearData!I$2:I$49, PreviousYearData!$A$2:$A$49, Calculations!$A24, PreviousYearData!$C$2:$C$49, Calculations!$B24) -> 324671.22 | I24: =SUMIFS(PreviousYearData!J$2:J$49, PreviousYearData!$A$2:$A$49, Calculations!$A24, PreviousYearData!$C$2:$C$49, Calculations!$B24) -> 376988.4 | J24: =SUMIFS(PreviousYearData!K$2:K$49, PreviousYearData!$A$2:$A$49, Calculations!$A24, PreviousYearData!$C$2:$C$49, Calculations!$B24) -> 311990.4
A25: Commercial | B25: =CurrentYearData!$S$2 -> WA | C25: =SUMIFS(PreviousYearData!D$2:D$49, PreviousYearData!$A$2:$A$49, Calculations!$A25, PreviousYearData!$C$2:$C$49, Calculations!$B25) -> 231219.55 | D25: =SUMIFS(PreviousYearData!E$2:E$49, PreviousYearData!$A$2:$A$49, Calculations!$A25, PreviousYearData!$C$2:$C$49, Calculations!$B25) -> 253492.2 | E25: =SUMIFS(PreviousYearData!F$2:F$49, PreviousYearData!$A$2:$A$49, Calculations!$A25, PreviousYearData!$C$2:$C$49, Calculations!$B25) -> 167982.07 | F25: =SUMIFS(PreviousYearData!G$2:G$49, PreviousYearData!$A$2:$A$49, Calculations!$A25, PreviousYearData!$C$2:$C$49, Calculations!$B25) -> 289024.44 | G25: =SUMIFS(PreviousYearData!H$2:H$49, PreviousYearData!$A$2:$A$49, Calculations!$A25, PreviousYearData!$C$2:$C$49, Calculations!$B25) -> 281658 | H25: =SUMIFS(PreviousYearData!I$2:I$49, PreviousYearData!$A$2:$A$49, Calculations!$A25, PreviousYearData!$C$2:$C$49, Calculations!$B25) -> 239974.38 | I25: =SUMIFS(PreviousYearData!J$2:J$49, PreviousYearData!$A$2:$A$49, Calculations!$A25, PreviousYearData!$C$2:$C$49, Calculations!$B25) -> 320440.14 | J25: =SUMIFS(PreviousYearData!K$2:K$49, PreviousYearData!$A$2:$A$49, Calculations!$A25, PreviousYearData!$C$2:$C$49, Calculations!$B25) -> 428986.8
A26: HR | B26: =CurrentYearData!$S$2 -> WA | C26: =SUMIFS(PreviousYearData!D$2:D$49, PreviousYearData!$A$2:$A$49, Calculations!$A26, PreviousYearData!$C$2:$C$49, Calculations!$B26) -> 150795.36 | D26: =SUMIFS(PreviousYearData!E$2:E$49, PreviousYearData!$A$2:$A$49, Calculations!$A26, PreviousYearData!$C$2:$C$49, Calculations!$B26) -> 266166.81 | E26: =SUMIFS(PreviousYearData!F$2:F$49, PreviousYearData!$A$2:$A$49, Calculations!$A26, PreviousYearData!$C$2:$C$49, Calculations!$B26) -> 217388.56 | F26: =SUMIFS(PreviousYearData!G$2:G$49, PreviousYearData!$A$2:$A$49, Calculations!$A26, PreviousYearData!$C$2:$C$49, Calculations!$B26) -> 188494.2 | G26: =SUMIFS(PreviousYearData!H$2:H$49, PreviousYearData!$A$2:$A$49, Calculations!$A26, PreviousYearData!$C$2:$C$49, Calculations!$B26) -> 295740.9 | H26: =SUMIFS(PreviousYearData!I$2:I$49, PreviousYearData!$A$2:$A$49, Calculations!$A26, PreviousYearData!$C$2:$C$49, Calculations!$B26) -> 310555.08 | I26: =SUMIFS(PreviousYearData!J$2:J$49, PreviousYearData!$A$2:$A$49, Calculations!$A26, PreviousYearData!$C$2:$C$49, Calculations!$B26) -> 452386.08 | J26: =SUMIFS(PreviousYearData!K$2:K$49, PreviousYearData!$A$2:$A$49, Calculations!$A26, PreviousYearData!$C$2:$C$49, Calculations!$B26) -> 428986.8
B28: =CurrentYearData!$S$2 -> WA | C28: =SUM(C22:C27) -> 1005302.4 | D28: =SUM(D22:D27) -> 1267461 | E28: =SUM(E22:E27) -> 988129.8 | F28: =SUM(F22:F27) -> 1256628 | G28: =SUM(G22:G27) -> 1408290 | H28: =SUM(H22:H27) -> 1411614 | I28: =SUM(I22:I27) -> 1884942 | J28: =SUM(J22:J27) -> 1949940
A31: Customer Satisfaction Data (%)
A32: Satisfaction | B32: State | C32: PY | D32: PY Var | E32: CY | F32: CY Var
A33: Satisfaction | B33: MI | C33: 0.81 | D33: =1-C33 -> 0.19 | E33: 0.83 | F33: =1-E33 -> 0.17
A34: Satisfaction | B34: TX | C34: 0.83 | D34: =1-C34 -> 0.17 | E34: 0.85 | F34: =1-E34 -> 0.15
A35: Satisfaction | B35: CO | C35: 0.88 | D35: =1-C35 -> 0.12 | E35: 0.92 | F35: =1-E35 -> 0.08
A36: Satisfaction | B36: VA | C36: 0.76 | D36: =1-C36 -> 0.24 | E36: 0.81 | F36: =1-E36 -> 0.19
A37: Satisfaction | B37: KS | C37: 0.76 | D37: =1-C37 -> 0.24 | E37: 0.82 | F37: =1-E37 -> 0.18
A38: Satisfaction | B38: FL | C38: 0.72 | D38: =1-C38 -> 0.28 | E38: 0.75 | F38: =1-E38 -> 0.25
A39: Satisfaction | B39: WA | C39: 0.72 | D39: =1-C39 -> 0.28 | E39: 0.8 | F39: =1-E39 -> 0.2
A40: Satisfaction | B40: NY | C40: 0.83 | D40: =1-C40 -> 0.17 | E40: 0.9 | F40: =1-E40 -> 0.1
B42: =CurrentYearData!$S$2 -> WA | C42: =VLOOKUP($B42,$B$33:$F$40, COLUMN(B1), 0) -> 0.72 | D42: =VLOOKUP($B42,$B$33:$F$40, COLUMN(C1), 0) -> 0.28 | E42: =VLOOKUP($B42,$B$33:$F$40, COLUMN(D1), 0) -> 0.8 | F42: =VLOOKUP($B42,$B$33:$F$40, COLUMN(E1), 0) -> 0.2
A45: Sales by Year
A46: Year | B46: State | C46: Actual | D46: Budget | E46: Trend
A47: 2014 | B47: =CurrentYearData!$S$2 -> WA | C47: {=SUMPRODUCT((HistoricalRevenue!$A$2:$A$18=C$46)*(HistoricalRevenue!$C$2:$C$18=$B$47)*(PreviousYearData!$D$1:$K$1=$A47)*(HistoricalRevenue!$D$2:$K$18))/1000} -> 1085.7266 | D47: {=SUMPRODUCT((HistoricalRevenue!$A$2:$A$18=D$46)*(HistoricalRevenue!$C$2:$C$18=$B$47)*(PreviousYearData!$D$1:$K$1=$A47)*(HistoricalRevenue!$D$2:$K$18))/1000} -> 1095.7266 | E47: =C47*$F$47 -> 2171.4532 | F47: 2
A48: 2015 | B48: =CurrentYearData!$S$2 -> WA | C48: {=SUMPRODUCT((HistoricalRevenue!$A$2:$A$18=C$46)*(HistoricalRevenue!$C$2:$C$18=$B$47)*(PreviousYearData!$D$1:$K$1=$A48)*(HistoricalRevenue!$D$2:$K$18))/1000} -> 1343.5087 | D48: {=SUMPRODUCT((HistoricalRevenue!$A$2:$A$18=D$46)*(HistoricalRevenue!$C$2:$C$18=$B$47)*(PreviousYearData!$D$1:$K$1=$A48)*(HistoricalRevenue!$D$2:$K$18))/1000} -> 1437.5543 | E48: =C48*$F$47 -> 2687.0173
A49: 2016 | B49: =CurrentYearData!$S$2 -> WA | C49: {=SUMPRODUCT((HistoricalRevenue!$A$2:$A$18=C$46)*(HistoricalRevenue!$C$2:$C$18=$B$47)*(PreviousYearData!$D$1:$K$1=$A49)*(HistoricalRevenue!$D$2:$K$18))/1000} -> 1126.468 | D49: {=SUMPRODUCT((HistoricalRevenue!$A$2:$A$18=D$46)*(HistoricalRevenue!$C$2:$C$18=$B$47)*(PreviousYearData!$D$1:$K$1=$A49)*(HistoricalRevenue!$D$2:$K$18))/1000} -> 1092.6739 | E49: =C49*$F$47 -> 2252.9359
A50: 2017 | B50: =CurrentYearData!$S$2 -> WA | C50: {=SUMPRODUCT((HistoricalRevenue!$A$2:$A$18=C$46)*(HistoricalRevenue!$C$2:$C$18=$B$47)*(PreviousYearData!$D$1:$K$1=$A50)*(HistoricalRevenue!$D$2:$K$18))/1000} -> 1432.5559 | D50: {=SUMPRODUCT((HistoricalRevenue!$A$2:$A$18=D$46)*(HistoricalRevenue!$C$2:$C$18=$B$47)*(PreviousYearData!$D$1:$K$1=$A50)*(HistoricalRevenue!$D$2:$K$18))/1000} -> 1332.277 | E50: =C50*$F$47 -> 2865.1118
A51: 2018 | B51: =CurrentYearData!$S$2 -> WA | C51: {=SUMPRODUCT((HistoricalRevenue!$A$2:$A$18=C$46)*(HistoricalRevenue!$C$2:$C$18=$B$47)*(PreviousYearData!$D$1:$K$1=$A51)*(HistoricalRevenue!$D$2:$K$18))/1000} -> 1478.7045 | D51: {=SUMPRODUCT((HistoricalRevenue!$A$2:$A$18=D$46)*(HistoricalRevenue!$C$2:$C$18=$B$47)*(PreviousYearData!$D$1:$K$1=$A51)*(HistoricalRevenue!$D$2:$K$18))/1000} -> 1523.0656 | E51: =C51*$F$47 -> 2957.409
...

Sheet Dashboard
B5: Expenditure | C5: PY | D5: CY | E5: Var %
B6: Operations | C6: =Calculations!I22/1000 -> 320.44014 | D6: =Calculations!J22/1000 -> 428.9868 | E6: =(D6-C6)/C6 -> 0.33874239
B7: Strategy | C7: =Calculations!I23/1000 -> 414.68724 | D7: =Calculations!J23/1000 -> 350.9892 | E7: =(D7-C7)/C7 -> -0.15360502
B8: Finance | C8: =Calculations!I24/1000 -> 376.9884 | D8: =Calculations!J24/1000 -> 311.9904 | E8: =(D8-C8)/C8 -> -0.17241379
B9: Commercial | C9: =Calculations!I25/1000 -> 320.44014 | D9: =Calculations!J25/1000 -> 428.9868 | E9: =(D9-C9)/C9 -> 0.33874239
B10: HR | C10: =Calculations!I26/1000 -> 452.38608 | D10: =Calculations!J26/1000 -> 428.9868 | E10: =(D10-C10)/C10 -> -0.051724138
B12: Total | C12: =SUM(C6:C10) -> 1884.942 | D12: =SUM(D6:D10) -> 1949.94 | E12: =(D12-C12)/C12 -> 0.034482759
